<?xml version="1.0"?>
<robot xmlns:xacro="http://wiki.ros.org/xacro">
  <xacro:include filename="$(find kuka_resources)/urdf/common_constants.xacro"/>
  <xacro:include filename="$(find kuka_resources)/urdf/common_materials.xacro"/>

  <xacro:macro name="kuka_kr6r700sixx" params="prefix">
    <link name="${prefix}base_link">
      <visual>
        <origin xyz="0 0 0" rpy="0 0 0" />
        <geometry>
          <mesh filename="package://kuka_kr6_support/meshes/kr6_agilus/visual/base_link.dae" />
        </geometry>
        <xacro:material_kuka_pedestal />
      </visual>
      <collision>
        <origin xyz="0 0 0" rpy="0 0 0" />
        <geometry>
          <mesh filename="package://kuka_kr6_support/meshes/kr6_agilus/collision/base_link.stl" />
        </geometry>
      </collision>
      <inertial>
        <origin
          xyz="0.0025008 -0.00040911 0.020867"
          rpy="0 0 0" />
        <mass
          value="0.59584" />
        <inertia
          ixx="0.0016223"
          ixy="-4.778E-05"
          ixz="-4.76E-06"
          iyy="0.0016219"
          iyz="1.7931E-05"
          izz="0.0027169" />
      </inertial>
    </link>
    <link name="${prefix}link_1">
      <visual>
        <origin xyz="0 0 0" rpy="0 0 0" />
        <geometry>
          <mesh filename="package://kuka_kr6_support/meshes/kr6_agilus/visual/link_1.dae" />
        </geometry>
        <xacro:material_kuka_orange />
      </visual>
      <collision>
        <origin xyz="0 0 0" rpy="0 0 0" />
        <geometry>
          <mesh filename="package://kuka_kr6_support/meshes/kr6_agilus/collision/link_1.stl" />
        </geometry>
      </collision>
      <inertial>
        <origin
          xyz="0.012509 2.7441E-05 0.049639"
          rpy="0 0 0" />
        <mass
          value="0.25526" />
        <inertia
          ixx="0.00023408"
          ixy="1.7779E-07"
          ixz="-2.7415E-05"
          iyy="0.00068215"
          iyz="-2.1813E-07"
          izz="0.0005853" />
      </inertial>
    </link>
    <link name="${prefix}link_2">
      <visual>
        <origin xyz="0 0 0" rpy="0 0 0" />
        <geometry>
          <mesh filename="package://kuka_kr6_support/meshes/kr6r700sixx/visual/link_2.dae" />
        </geometry>
        <xacro:material_kuka_orange />
      </visual>
      <collision>
        <origin xyz="0 0 0" rpy="0 0 0" />
        <geometry>
          <mesh filename="package://kuka_kr6_support/meshes/kr6r700sixx/collision/link_2.stl" />
        </geometry>
      </collision>
      <inertial>
        <origin
          xyz="-0.012468 8.4775E-08 0.056546"
          rpy="0 0 0" />
        <mass
          value="0.15994" />
        <inertia
          ixx="0.0001033"
          ixy="-1.1899E-06"
          ixz="1.4336E-05"
          iyy="0.00017682"
          iyz="-3.0046E-10"
          izz="0.00012114" />
      </inertial>
    </link>
    <link name="${prefix}link_3">
      <visual>
        <origin xyz="0 0 0" rpy="0 0 0" />
        <geometry>
          <mesh filename="package://kuka_kr6_support/meshes/kr6_agilus/visual/link_3.dae" />
        </geometry>
        <xacro:material_kuka_orange />
      </visual>
      <collision>
        <origin xyz="0 0 0" rpy="0 0 0" />
        <geometry>
          <mesh filename="package://kuka_kr6_support/meshes/kr6_agilus/collision/link_3.stl" />
        </geometry>
      </collision>
      <inertial>
        <origin
          xyz="0.00033799 -3.3709E-13 0.05506"
          rpy="0 0 0" />
        <mass
          value="0.094737" />
        <inertia
          ixx="4.6661E-05"
          ixy="-8.3316E-18"
          ixz="-1.3753E-06"
          iyy="5.724E-05"
          iyz="-6.333E-17"
          izz="3.0064E-05" />
      </inertial>      
    </link>
    <link name="${prefix}link_4">
      <visual>
        <origin xyz="0 0 0" rpy="0 0 0" />
        <geometry>
          <mesh filename="package://kuka_kr6_support/meshes/kr6r700sixx/visual/link_4.dae" />
        </geometry>
        <xacro:material_kuka_orange />
      </visual>
      <collision>
        <origin xyz="0 0 0" rpy="0 0 0" />
        <geometry>
          <mesh filename="package://kuka_kr6_support/meshes/kr6r700sixx/collision/link_4.stl" />
        </geometry>
      </collision>
      <inertial>
        <origin
          xyz="5.1726E-05 -0.00020169 0.049677"
          rpy="0 0 0" />
        <mass
          value="0.064903" />
        <inertia
          ixx="4.8255E-05"
          ixy="7.7645E-12"
          ixz="1.8579E-10"
          iyy="5.2526E-05"
          iyz="1.7525E-06"
          izz="2.2147E-05" />
      </inertial>
    </link>
    <link name="${prefix}link_5">
      <visual>
        <origin xyz="0 0 0" rpy="0 0 0" />
        <geometry>
          <mesh filename="package://kuka_kr6_support/meshes/kr6_agilus/visual/link_5.dae" />
        </geometry>
        <xacro:material_kuka_orange />
      </visual>
      <collision>
        <origin xyz="0 0 0" rpy="0 0 0" />
        <geometry>
          <mesh filename="package://kuka_kr6_support/meshes/kr6_agilus/collision/link_5.stl" />
        </geometry>
      </collision>
      <inertial>
        <origin
          xyz="-0.00048971 -0.00019645 0.058588"
          rpy="0 0 0" />
        <mass
          value="0.058288" />
        <inertia
          ixx="3.2343E-05"
          ixy="-2.1864E-09"
          ixz="-5.5709E-07"
          iyy="3.3707E-05"
          iyz="-8.298E-09"
          izz="1.3619E-05" />
      </inertial>
    </link>
    <link name="${prefix}link_6">
      <visual>
        <origin xyz="0 0 0" rpy="0 0 0" />
        <geometry>
          <mesh filename="package://kuka_kr6_support/meshes/kr6_agilus/visual/link_6.dae" />
        </geometry>
        <xacro:material_kuka_pedestal />
      </visual>
      <collision>
        <origin xyz="0 0 0" rpy="0 0 0" />
        <geometry>
          <mesh filename="package://kuka_kr6_support/meshes/kr6_agilus/collision/link_6.stl" />
        </geometry>
      </collision>
      <inertial>
        <origin
          xyz="-7.0358E-05 -7.9344E-05 0.026287"
          rpy="0 0 0" />
        <mass
          value="0.012172" />
        <inertia
          ixx="3.3095E-06"
          ixy="7.7004E-11"
          ixz="1.1212E-08"
          iyy="4.9286E-06"
          iyz="3.1423E-08"
          izz="4.4692E-06" />
      </inertial>
    </link>
    <!-- This frame corresponds to the $FLANGE coordinate system in KUKA KRC controllers. -->
    <link name="${prefix}tool0" />

    <joint name="${prefix}joint_a1" type="revolute">
      <origin xyz="0 0 0.4" rpy="0 0 0"/>
      <parent link="${prefix}base_link"/>
      <child link="${prefix}link_1"/>
      <axis xyz="0 0 -1"/>
      <limit lower="${-170 * DEG2RAD}" upper="${170 * DEG2RAD}" effort="0" velocity="${360 * DEG2RAD}"/>
    </joint>
    <joint name="${prefix}joint_a2" type="revolute">
      <origin xyz="0.025 0 0" rpy="0 0 0"/>
      <parent link="${prefix}link_1"/>
      <child link="${prefix}link_2"/>
      <axis xyz="0 1 0"/>
      <limit lower="${-190 * DEG2RAD}" upper="${45 * DEG2RAD}" effort="0" velocity="${300 * DEG2RAD}"/>
    </joint>
    <joint name="${prefix}joint_a3" type="revolute">
      <origin xyz="0.315 0 0" rpy="0 0 0"/>
      <parent link="${prefix}link_2"/>
      <child link="${prefix}link_3"/>
      <axis xyz="0 1 0"/>
      <limit lower="${-120 * DEG2RAD}" upper="${156 * DEG2RAD}" effort="0" velocity="${360 * DEG2RAD}"/>
    </joint>
    <joint name="${prefix}joint_a4" type="revolute">
      <origin xyz="0 0 0.035" rpy="0 0 0"/>
      <parent link="${prefix}link_3"/>
      <child link="${prefix}link_4"/>
      <axis xyz="-1 0 0"/>
      <limit lower="${-185 * DEG2RAD}" upper="${185 * DEG2RAD}" effort="0" velocity="${381 * DEG2RAD}"/>
    </joint>
    <joint name="${prefix}joint_a5" type="revolute">
      <origin xyz="0.365 0 0" rpy="0 0 0"/>
      <parent link="${prefix}link_4"/>
      <child link="${prefix}link_5"/>
      <axis xyz="0 1 0"/>
      <limit lower="${-120 * DEG2RAD}" upper="${120 * DEG2RAD}" effort="0" velocity="${388 * DEG2RAD}"/>
    </joint>
    <joint name="${prefix}joint_a6" type="revolute">
      <origin xyz="0.080 0 0" rpy="0 0 0"/>
      <parent link="${prefix}link_5"/>
      <child link="${prefix}link_6"/>
      <axis xyz="-1 0 0"/>
      <limit lower="${-350 * DEG2RAD}" upper="${350 * DEG2RAD}" effort="0" velocity="${615 * DEG2RAD}"/>
    </joint>
    <joint name="${prefix}joint_a6-tool0" type="fixed">
      <parent link="${prefix}link_6"/>
      <child link="${prefix}tool0"/>
      <origin xyz="0 0 0" rpy="0 ${90 * DEG2RAD} 0"/>
    </joint>

    <!-- ROS base_link to KUKA $ROBROOT coordinate system transform -->
    <link name="${prefix}base" />
    <joint name="${prefix}base_link-base" type="fixed">
      <origin xyz="0 0 0" rpy="0 0 0"/>
      <parent link="${prefix}base_link"/>
      <child link="${prefix}base"/>
    </joint>
  </xacro:macro>
</robot>
